Workbook

Sheet Respuestas de formulario 1
A1: Marca temporal | B1: Tipo de solicitud | C1: Usted es: | D1: Tipo de documento | E1: Número de identificación. | F1: Nombre completo del paciente: | G1: Edad | H1: Sexo | I1: Número de teléfono | J1: Dirección. | K1: Correo electrónico. | L1: Población diferencial. | M1: Seleccione su EPS | N1: Régimen. | O1: Indique la sede (CAMINO o PASO) donde recibió la atención. | P1: Servicio o área a la que a vinculado su opinión. | Q1: Describa su solicitud. | R1: Columna 17

Sheet Plantillas
A1: CÓDIGO | B1: TIPOLOGÍA | C1: TEXTO DE RESPUESTA
A2: T1 | B2: Oportunidad en citas de especialista | C2: Reciba un cordial saludo. Agradecemos que nos haya compartido su experiencia. Verificamos su caso con el área asistencial y se realizó la gestión ante el prestador para garantizar la asignación de su cita dentro del término establecido en la Resolución 1552 de 2013. Quedamos atentos a cualquier inquietud adicional.
A3: T2 | B3: Entrega de medicamentos | C3: Reciba un cordial saludo. Revisamos su solicitud con el servicio farmacéutico y se adelantó la gestión para garantizar el suministro de su medicamento. Su tratamiento continuará sin interrupciones según el plan de manejo médico. Agradecemos su comprensión.
A4: T3 | B4: Programación de cirugías | C4: Reciba un cordial saludo. Su caso fue revisado con el área quirúrgica, que adelantó la gestión para la programación de su procedimiento. La fecha definitiva será informada al contacto que registró en su solicitud. Agradecemos su paciencia.
A5: T4 | B5: Trato del personal | C5: Reciba un cordial saludo. Lamentamos la situación que nos describe. Su caso fue remitido al área responsable y a Talento Humano para la revisión correspondiente y las acciones de mejora a que haya lugar. Reiteramos nuestro compromiso con una atención humanizada y le agradecemos habernos informado.
A6: T5 | B6: Autorizaciones y trámites administrativos | C6: Reciba un cordial saludo. Realizamos el seguimiento ante el área de Autorizaciones y su trámite fue gestionado. Puede verificar el estado del servicio en nuestros canales de atención. Quedamos atentos a cualquier inquietud adicional.
A7: T6 | B7: Infraestructura, aseo y comodidad | C7: Reciba un cordial saludo. Trasladamos su observación al área de servicios generales e infraestructura, que adelantó la revisión y las acciones correctivas correspondientes en la sede. Agradecemos su reporte: nos ayuda a mejorar las condiciones de atención.
A8: T7 | B8: Facturación y cobros | C8: Reciba un cordial saludo. Su solicitud fue revisada con el área de facturación, donde se verificó el cobro y se realizaron los ajustes que correspondían. Agradecemos su comprensión.
A9: T8 | B9: Agradecimiento por felicitación | C9: Reciba un cordial saludo. Agradecemos el tiempo que dedicó a reconocer la labor de nuestro equipo. Su mensaje fue compartido con el área y con las personas que menciona: este tipo de comentarios motiva e impulsa nuestro compromiso con la atención. Gracias por confiar en MiRed IPS.

Sheet LÉEME
A1: SISTEMA PQRS v4 — MiRed Barranquilla IPS S.A.S.
A2: Todo se opera desde la plataforma web. Este libro es la base de datos.
A4: Cómo funciona
A5: La plataforma web es el único sitio donde se trabaja: radicar, analizar, direccionar al área, registrar la respuesta del responsable, responder al usuario y ver el tablero. Este libro guarda los datos y sirve de respaldo y de fuente para los informes.
A7: Hojas
A8: • Consolidado_PQRS — una fila por PQRS, con las tres fechas separadas: la de la PQRS (la que trae el documento del usuario), la de recepción en el SIAU y la de radicación en el sistema, que es desde la que corre el término legal.
A9: • Trazabilidad — bitácora de cada acción: quién, cuándo y qué hizo con cada radicado.
A10: • Responsables — áreas, nombres y correos. Se administra desde la plataforma.
A11: • Mapeo_Formulario — equivalencia entre las preguntas de tu Google Form y los campos del sistema.
A12: • Config — términos legales, festivos, listas y parámetros.
A14: El flujo de una PQRS
A15: 1. Se radica (presencial en la plataforma, por el formulario del QR o por correo) → el usuario recibe el acuse.
... A19: 5. El SIAU ajusta el texto para el usuario y cierra: sale el correo de respuesta final.

Sheet Consolidado_PQRS
A1: 🗂 CONSOLIDADO DE PQRS — base de datos del sistema
A2: La gestión se hace en la plataforma web. Esta hoja es el respaldo: evita editarla a mano.
A3: IDENTIFICACIÓN Y FECHAS | G3: SOLICITANTE | N3: AFILIADO / PACIENTE | V3: HECHO | AE3: TÉRMINOS | AK3: GESTIÓN | AU3: NOTIFICACIONES Y CONTROL
A4: CÓDIGO DE RADICACIÓN | B4: CANAL DE RECEPCIÓN | C4: FECHA DE LA PQRS | D4: FECHA DE RECEPCIÓN | E4: FECHA DE RADICACIÓN | F4: MARCA TEMPORAL | G4: TIPO SOLICITANTE | H4: TIPO DOC SOLICITANTE | I4: N° DOC SOLICITANTE | J4: NOMBRE SOLICITANTE | K4: TELÉFONO | L4: CORREO ELECTRÓNICO | M4: DIRECCIÓN | N4: TIPO DOC AFILIADO | O4: N° DOC AFILIADO | P4: NOMBRE AFILIADO | Q4: EDAD | R4: SEXO | S4: POBLACIÓN DIFERENCIAL | T4: EPS / PRESTADOR | U4: RÉGIMEN | V4: SEDE | W4: SERVICIO DONDE OCURRE | X4: SERVICIO ESPECÍFICO | Y4: MODALIDAD DE ATENCIÓN | Z4: DEPARTAMENTO | AA4: TIPO DE PQRS | AB4: CLASIFICACIÓN INTERNA | AC4: TIPOLOGÍA | AD4: DESCRIPCIÓN | AE4: ENTIDAD PRESENTADA | AF4: TÉRMINO (días) | AG4: TIPO DE DÍA | AH4: FECHA MÁXIMA DE RESPUESTA | AI4: SEMÁFORO | AJ4: DÍAS TRANSCURRIDOS | AK4: ESTADO | AL4: RESPONSABLE ASIGNADO | AM4: CORREO RESPONSABLE | AN4: FECHA ENVÍO AL ÁREA | AO4: REDIRECCIONAMIENTOS | AP4: RESPUESTA DEL RESPONSABLE | AQ4: FECHA RESPUESTA DEL RESPONSABLE | AR4: RESPUESTA ENVIADA AL USUARIO | AS4: FECHA DE RESPUESTA AL USUARIO | AT4: ESTADO DE OPORTUNIDAD | AU4: FECHA NOTIF. RECEPCIÓN | AV4: FECHA NOTIF. AL ÁREA | AW4: FECHA NOTIF. EN GESTIÓN | AX4: FECHA NOTIF. CIERRE | AY4: OBSERVACIONES | AZ4: ID CORREO | BA4: REGISTRADO POR
AF5: =IF($AA18="","",IF(LEFT(UPPER(TRIM($AA18)),8)="FELICITA","N/A",IF($AE18="","",IFERROR(VLOOKUP(UPPER(TRIM($AE18)),Config!$A$6:$D$8,2,FALSE),IFERROR(VLOOKUP(IF(LEFT(UPPER(TRIM($AE18)),5)="SUPER","SUPER SALUD",IF(LEFT(UPPER(TRIM($AE18)),8)="SECRETAR","SECRETARIA DE SALUD",IF(LEFT(UPPER(TRIM($AE18)),4)="SEDE","SEDE",UPPER(TRIM($AE18))))),Config!$A$6:$D$8,2,FALSE),"⚠"))))) | AG5: =IF($AA18="","",IF(LEFT(UPPER(TRIM($AA18)),8)="FELICITA","N/A",IF($AE18="","",IFERROR(VLOOKUP(UPPER(TRIM($AE18)),Config!$A$6:$D$8,3,FALSE),IFERROR(VLOOKUP(IF(LEFT(UPPER(TRIM($AE18)),5)="SUPER","SUPER SALUD",IF(LEFT(UPPER(TRIM($AE18)),8)="SECRETAR","SECRETARIA DE SALUD",IF(LEFT(UPPER(TRIM($AE18)),4)="SEDE","SEDE",UPPER(TRIM($AE18))))),Config!$A$6:$D$8,3,FALSE),""))))) | AH5: =IF(OR($E18="",NOT(ISNUMBER($E18)),$AF18="",$AF18="N/A",NOT(ISNUMBER($AF18))),"",IF($AG18="Hábiles",WORKDAY(INT($E18),$AF18,Config!$F$6:$F$39),INT($E18)+$AF18)) | AI5: =IF($E18="","",IF(LEFT(UPPER(TRIM($AA18)),8)="FELICITA","⭐ Felicitación",IF(NOT(ISNUMBER($E18)),"⚠ Revisar fecha",IF(UPPER(TRIM($AK18))="RESPONDIDA - CERRADA","✅ Cerrada",IF($AE18="","⚠ Falta entidad",IF($AH18="","⚠ Revisar término",IF(TODAY()>$AH18,"🔴 Vencida",IF($AH18-TODAY()<=Config!$B$12,"🟡 Próxima a vencer","🟢 En término")))))))) | AJ5: =IF(OR($E18="",NOT(ISNUMBER($E18))),"",IF(ISNUMBER($AS18),MAX(0,INT($AS18)-INT($E18)),MAX(0,TODAY()-INT($E18)))) | AT5: =IF(OR($AS18="",NOT(ISNUMBER($AS18)),$AH18=""),"",IF(INT($AS18)<=$AH18,"A tiempo","Fuera de término"))
AF6: =IF($AA19="","",IF(LEFT(UPPER(TRIM($AA19)),8)="FELICITA","N/A",IF($AE19="","",IFERROR(VLOOKUP(UPPER(TRIM($AE19)),Config!$A$6:$D$8,2,FALSE),IFERROR(VLOOKUP(IF(LEFT(UPPER(TRIM($AE19)),5)="SUPER","SUPER SALUD",IF(LEFT(UPPER(TRIM($AE19)),8)="SECRETAR","SECRETARIA DE SALUD",IF(LEFT(UPPER(TRIM($AE19)),4)="SEDE","SEDE",UPPER(TRIM($AE19))))),Config!$A$6:$D$8,2,FALSE),"⚠"))))) | AG6: =IF($AA19="","",IF(LEFT(UPPER(TRIM($AA19)),8)="FELICITA","N/A",IF($AE19="","",IFERROR(VLOOKUP(UPPER(TRIM($AE19)),Config!$A$6:$D$8,3,FALSE),IFERROR(VLOOKUP(IF(LEFT(UPPER(TRIM($AE19)),5)="SUPER","SUPER SALUD",IF(LEFT(UPPER(TRIM($AE19)),8)="SECRETAR","SECRETARIA DE SALUD",IF(LEFT(UPPER(TRIM($AE19)),4)="SEDE","SEDE",UPPER(TRIM($AE19))))),Config!$A$6:$D$8,3,FALSE),""))))) | AH6: =IF(OR($E19="",NOT(ISNUMBER($E19)),$AF19="",$AF19="N/A",NOT(ISNUMBER($AF19))),"",IF($AG19="Hábiles",WORKDAY(INT($E19),$AF19,Config!$F$6:$F$39),INT($E19)+$AF19)) | AI6: =IF($E19="","",IF(LEFT(UPPER(TRIM($AA19)),8)="FELICITA","⭐ Felicitación",IF(NOT(ISNUMBER($E19)),"⚠ Revisar fecha",IF(UPPER(TRIM($AK19))="RESPONDIDA - CERRADA","✅ Cerrada",IF($AE19="","⚠ Falta entidad",IF($AH19="","⚠ Revisar término",IF(TODAY()>$AH19,"🔴 Vencida",IF($AH19-TODAY()<=Config!$B$12,"🟡 Próxima a vencer","🟢 En término")))))))) | AJ6: =IF(OR($E19="",NOT(ISNUMBER($E19))),"",IF(ISNUMBER($AS19),MAX(0,INT($AS19)-INT($E19)),MAX(0,TODAY()-INT($E19)))) | AT6: =IF(OR($AS19="",NOT(ISNUMBER($AS19)),$AH19=""),"",IF(INT($AS19)<=$AH19,"A tiempo","Fuera de término"))
AF7: =IF($AA20="","",IF(LEFT(UPPER(TRIM($AA20)),8)="FELICITA","N/A",IF($AE20="","",IFERROR(VLOOKUP(UPPER(TRIM($AE20)),Config!$A$6:$D$8,2,FALSE),IFERROR(VLOOKUP(IF(LEFT(UPPER(TRIM($AE20)),5)="SUPER","SUPER SALUD",IF(LEFT(UPPER(TRIM($AE20)),8)="SECRETAR","SECRETARIA DE SALUD",IF(LEFT(UPPER(TRIM($AE20)),4)="SEDE","SEDE",UPPER(TRIM($AE20))))),Config!$A$6:$D$8,2,FALSE),"⚠"))))) | AG7: =IF($AA20="","",IF(LEFT(UPPER(TRIM($AA20)),8)="FELICITA","N/A",IF($AE20="","",IFERROR(VLOOKUP(UPPER(TRIM($AE20)),Config!$A$6:$D$8,3,FALSE),IFERROR(VLOOKUP(IF(LEFT(UPPER(TRIM($AE20)),5)="SUPER","SUPER SALUD",IF(LEFT(UPPER(TRIM($AE20)),8)="SECRETAR","SECRETARIA DE SALUD",IF(LEFT(UPPER(TRIM($AE20)),4)="SEDE","SEDE",UPPER(TRIM($AE20))))),Config!$A$6:$D$8,3,FALSE),""))))) | AH7: =IF(OR($E20="",NOT(ISNUMBER($E20)),$AF20="",$AF20="N/A",NOT(ISNUMBER($AF20))),"",IF($AG20="Hábiles",WORKDAY(INT($E20),$AF20,Config!$F$6:$F$39),INT($E20)+$AF20)) | AI7: =IF($E20="","",IF(LEFT(UPPER(TRIM($AA20)),8)="FELICITA","⭐ Felicitación",IF(NOT(ISNUMBER($E20)),"⚠ Revisar fecha",IF(UPPER(TRIM($AK20))="RESPONDIDA - CERRADA","✅ Cerrada",IF($AE20="","⚠ Falta entidad",IF($AH20="","⚠ Revisar término",IF(TODAY()>$AH20,"🔴 Vencida",IF($AH20-TODAY()<=Config!$B$12,"🟡 Próxima a vencer","🟢 En término")))))))) | AJ7: =IF(OR($E20="",NOT(ISNUMBER($E20))),"",IF(ISNUMBER($AS20),MAX(0,INT($AS20)-INT($E20)),MAX(0,TODAY()-INT($E20)))) | AT7: =IF(OR($AS20="",NOT(ISNUMBER($AS20)),$AH20=""),"",IF(INT($AS20)<=$AH20,"A tiempo","Fuera de término"))
AF8: =IF($AA21="","",IF(LEFT(UPPER(TRIM($AA21)),8)="FELICITA","N/A",IF($AE21="","",IFERROR(VLOOKUP(UPPER(TRIM($AE21)),Config!$A$6:$D$8,2,FALSE),IFERROR(VLOOKUP(IF(LEFT(UPPER(TRIM($AE21)),5)="SUPER","SUPER SALUD",IF(LEFT(UPPER(TRIM($AE21)),8)="SECRETAR","SECRETARIA DE SALUD",IF(LEFT(UPPER(TRIM($AE21)),4)="SEDE","SEDE",UPPER(TRIM($AE21))))),Config!$A$6:$D$8,2,FALSE),"⚠"))))) | AG8: =IF($AA21="","",IF(LEFT(UPPER(TRIM($AA21)),8)="FELICITA","N/A",IF($AE21="","",IFERROR(VLOOKUP(UPPER(TRIM($AE21)),Config!$A$6:$D$8,3,FALSE),IFERROR(VLOOKUP(IF(LEFT(UPPER(TRIM($AE21)),5)="SUPER","SUPER SALUD",IF(LEFT(UPPER(TRIM($AE21)),8)="SECRETAR","SECRETARIA DE SALUD",IF(LEFT(UPPER(TRIM($AE21)),4)="SEDE","SEDE",UPPER(TRIM($AE21))))),Config!$A$6:$D$8,3,FALSE),""))))) | AH8: =IF(OR($E21="",NOT(ISNUMBER($E21)),$AF21="",$AF21="N/A",NOT(ISNUMBER($AF21))),"",IF($AG21="Hábiles",WORKDAY(INT($E21),$AF21,Config!$F$6:$F$39),INT($E21)+$AF21)) | AI8: =IF($E21="","",IF(LEFT(UPPER(TRIM($AA21)),8)="FELICITA","⭐ Felicitación",IF(NOT(ISNUMBER($E21)),"⚠ Revisar fecha",IF(UPPER(TRIM($AK21))="RESPONDIDA - CERRADA","✅ Cerrada",IF($AE21="","⚠ Falta entidad",IF($AH21="","⚠ Revisar término",IF(TODAY()>$AH21,"🔴 Vencida",IF($AH21-TODAY()<=Config!$B$12,"🟡 Próxima a vencer","🟢 En término")))))))) | AJ8: =IF(OR($E21="",NOT(ISNUMBER($E21))),"",IF(ISNUMBER($AS21),MAX(0,INT($AS21)-INT($E21)),MAX(0,TODAY()-INT($E21)))) | AT8: =IF(OR($AS21="",NOT(ISNUMBER($AS21)),$AH21=""),"",IF(INT($AS21)<=$AH21,"A tiempo","Fuera de término"))
AF9: =IF($AA22="","",IF(LEFT(UPPER(TRIM($AA22)),8)="FELICITA","N/A",IF($AE22="","",IFERROR(VLOOKUP(UPPER(TRIM($AE22)),Config!$A$6:$D$8,2,FALSE),IFERROR(VLOOKUP(IF(LEFT(UPPER(TRIM($AE22)),5)="SUPER","SUPER SALUD",IF(LEFT(UPPER(TRIM($AE22)),8)="SECRETAR","SECRETARIA DE SALUD",IF(LEFT(UPPER(TRIM($AE22)),4)="SEDE","SEDE",UPPER(TRIM($AE22))))),Config!$A$6:$D$8,2,FALSE),"⚠"))))) | AG9: =IF($AA22="","",IF(LEFT(UPPER(TRIM($AA22)),8)="FELICITA","N/A",IF($AE22="","",IFERROR(VLOOKUP(UPPER(TRIM($AE22)),Config!$A$6:$D$8,3,FALSE),IFERROR(VLOOKUP(IF(LEFT(UPPER(TRIM($AE22)),5)="SUPER","SUPER SALUD",IF(LEFT(UPPER(TRIM($AE22)),8)="SECRETAR","SECRETARIA DE SALUD",IF(LEFT(UPPER(TRIM($AE22)),4)="SEDE","SEDE",UPPER(TRIM($AE22))))),Config!$A$6:$D$8,3,FALSE),""))))) | AH9: =IF(OR($E22="",NOT(ISNUMBER($E22)),$AF22="",$AF22="N/A",NOT(ISNUMBER($AF22))),"",IF($AG22="Hábiles",WORKDAY(INT($E22),$AF22,Config!$F$6:$F$39),INT($E22)+$AF22)) | AI9: =IF($E22="","",IF(LEFT(UPPER(TRIM($AA22)),8)="FELICITA","⭐ Felicitación",IF(NOT(ISNUMBER($E22)),"⚠ Revisar fecha",IF(UPPER(TRIM($AK22))="RESPONDIDA - CERRADA","✅ Cerrada",IF($AE22="","⚠ Falta entidad",IF($AH22="","⚠ Revisar término",IF(TODAY()>$AH22,"🔴 Vencida",IF($AH22-TODAY()<=Config!$B$12,"🟡 Próxima a vencer","🟢 En término")))))))) | AJ9: =IF(OR($E22="",NOT(ISNUMBER($E22))),"",IF(ISNUMBER($AS22),MAX(0,INT($AS22)-INT($E22)),MAX(0,TODAY()-INT($E22)))) | AT9: =IF(OR($AS22="",NOT(ISNUMBER($AS22)),$AH22=""),"",IF(INT($AS22)<=$AH22,"A tiempo","Fuera de término"))
AF10: =IF($AA23="","",IF(LEFT(UPPER(TRIM($AA23)),8)="FELICITA","N/A",IF($AE23="","",IFERROR(VLOOKUP(UPPER(TRIM($AE23)),Config!$A$6:$D$8,2,FALSE),IFERROR(VLOOKUP(IF(LEFT(UPPER(TRIM($AE23)),5)="SUPER","SUPER SALUD",IF(LEFT(UPPER(TRIM($AE23)),8)="SECRETAR","SECRETARIA DE SALUD",IF(LEFT(UPPER(TRIM($AE23)),4)="SEDE","SEDE",UPPER(TRIM($AE23))))),Config!$A$6:$D$8,2,FALSE),"⚠"))))) | AG10: =IF($AA23="","",IF(LEFT(UPPER(TRIM($AA23)),8)="FELICITA","N/A",IF($AE23="","",IFERROR(VLOOKUP(UPPER(TRIM($AE23)),Config!$A$6:$D$8,3,FALSE),IFERROR(VLOOKUP(IF(LEFT(UPPER(TRIM($AE23)),5)="SUPER","SUPER SALUD",IF(LEFT(UPPER(TRIM($AE23)),8)="SECRETAR","SECRETARIA DE SALUD",IF(LEFT(UPPER(TRIM($AE23)),4)="SEDE","SEDE",UPPER(TRIM($AE23))))),Config!$A$6:$D$8,3,FALSE),""))))) | AH10: =IF(OR($E23="",NOT(ISNUMBER($E23)),$AF23="",$AF23="N/A",NOT(ISNUMBER($AF23))),"",IF($AG23="Hábiles",WORKDAY(INT($E23),$AF23,Config!$F$6:$F$39),INT($E23)+$AF23)) | AI10: =IF($E23="","",IF(LEFT(UPPER(TRIM($AA23)),8)="FELICITA","⭐ Felicitación",IF(NOT(ISNUMBER($E23)),"⚠ Revisar fecha",IF(UPPER(TRIM($AK23))="RESPONDIDA - CERRADA","✅ Cerrada",IF($AE23="","⚠ Falta entidad",IF($AH23="","⚠ Revisar término",IF(TODAY()>$AH23,"🔴 Vencida",IF($AH23-TODAY()<=Config!$B$12,"🟡 Próxima a vencer","🟢 En término")))))))) | AJ10: =IF(OR($E23="",NOT(ISNUMBER($E23))),"",IF(ISNUMBER($AS23),MAX(0,INT($AS23)-INT($E23)),MAX(0,TODAY()-INT($E23)))) | AT10: =IF(OR($AS23="",NOT(ISNUMBER($AS23)),$AH23=""),"",IF(INT($AS23)<=$AH23,"A tiempo","Fuera de término"))
AF11: =IF($AA24="","",IF(LEFT(UPPER(TRIM($AA24)),8)="FELICITA","N/A",IF($AE24="","",IFERROR(VLOOKUP(UPPER(TRIM($AE24)),Config!$A$6:$D$8,2,FALSE),IFERROR(VLOOKUP(IF(LEFT(UPPER(TRIM($AE24)),5)="SUPER","SUPER SALUD",IF(LEFT(UPPER(TRIM($AE24)),8)="SECRETAR","SECRETARIA DE SALUD",IF(LEFT(UPPER(TRIM($AE24)),4)="SEDE","SEDE",UPPER(TRIM($AE24))))),Config!$A$6:$D$8,2,FALSE),"⚠"))))) | AG11: =IF($AA24="","",IF(LEFT(UPPER(TRIM($AA24)),8)="FELICITA","N/A",IF($AE24="","",IFERROR(VLOOKUP(UPPER(TRIM($AE24)),Config!$A$6:$D$8,3,FALSE),IFERROR(VLOOKUP(IF(LEFT(UPPER(TRIM($AE24)),5)="SUPER","SUPER SALUD",IF(LEFT(UPPER(TRIM($AE24)),8)="SECRETAR","SECRETARIA DE SALUD",IF(LEFT(UPPER(TRIM($AE24)),4)="SEDE","SEDE",UPPER(TRIM($AE24))))),Config!$A$6:$D$8,3,FALSE),""))))) | AH11: =IF(OR($E24="",NOT(ISNUMBER($E24)),$AF24="",$AF24="N/A",NOT(ISNUMBER($AF24))),"",IF($AG24="Hábiles",WORKDAY(INT($E24),$AF24,Config!$F$6:$F$39),INT($E24)+$AF24)) | AI11: =IF($E24="","",IF(LEFT(UPPER(TRIM($AA24)),8)="FELICITA","⭐ Felicitación",IF(NOT(ISNUMBER($E24)),"⚠ Revisar fecha",IF(UPPER(TRIM($AK24))="RESPONDIDA - CERRADA","✅ Cerrada",IF($AE24="","⚠ Falta entidad",IF($AH24="","⚠ Revisar término",IF(TODAY()>$AH24,"🔴 Vencida",IF($AH24-TODAY()<=Config!$B$12,"🟡 Próxima a vencer","🟢 En término")))))))) | AJ11: =IF(OR($E24="",NOT(ISNUMBER($E24))),"",IF(ISNUMBER($AS24),MAX(0,INT($AS24)-INT($E24)),MAX(0,TODAY()-INT($E24)))) | AT11: =IF(OR($AS24="",NOT(ISNUMBER($AS24)),$AH24=""),"",IF(INT($AS24)<=$AH24,"A tiempo","Fuera de término"))
AF12: =IF($AA25="","",IF(LEFT(UPPER(TRIM($AA25)),8)="FELICITA","N/A",IF($AE25="","",IFERROR(VLOOKUP(UPPER(TRIM($AE25)),Config!$A$6:$D$8,2,FALSE),IFERROR(VLOOKUP(IF(LEFT(UPPER(TRIM($AE25)),5)="SUPER","SUPER SALUD",IF(LEFT(UPPER(TRIM($AE25)),8)="SECRETAR","SECRETARIA DE SALUD",IF(LEFT(UPPER(TRIM($AE25)),4)="SEDE","SEDE",UPPER(TRIM($AE25))))),Config!$A$6:$D$8,2,FALSE),"⚠"))))) | AG12: =IF($AA25="","",IF(LEFT(UPPER(TRIM($AA25)),8)="FELICITA","N/A",IF($AE25="","",IFERROR(VLOOKUP(UPPER(TRIM($AE25)),Config!$A$6:$D$8,3,FALSE),IFERROR(VLOOKUP(IF(LEFT(UPPER(TRIM($AE25)),5)="SUPER","SUPER SALUD",IF(LEFT(UPPER(TRIM($AE25)),8)="SECRETAR","SECRETARIA DE SALUD",IF(LEFT(UPPER(TRIM($AE25)),4)="SEDE","SEDE",UPPER(TRIM($AE25))))),Config!$A$6:$D$8,3,FALSE),""))))) | AH12: =IF(OR($E25="",NOT(ISNUMBER($E25)),$AF25="",$AF25="N/A",NOT(ISNUMBER($AF25))),"",IF($AG25="Hábiles",WORKDAY(INT($E25),$AF25,Config!$F$6:$F$39),INT($E25)+$AF25)) | AI12: =IF($E25="","",IF(LEFT(UPPER(TRIM($AA25)),8)="FELICITA","⭐ Felicitación",IF(NOT(ISNUMBER($E25)),"⚠ Revisar fecha",IF(UPPER(TRIM($AK25))="RESPONDIDA - CERRADA","✅ Cerrada",IF($AE25="","⚠ Falta entidad",IF($AH25="","⚠ Revisar término",IF(TODAY()>$AH25,"🔴 Vencida",IF($AH25-TODAY()<=Config!$B$12,"🟡 Próxima a vencer","🟢 En término")))))))) | AJ12: =IF(OR($E25="",NOT(ISNUMBER($E25))),"",IF(ISNUMBER($AS25),MAX(0,INT($AS25)-INT($E25)),MAX(0,TODAY()-INT($E25)))) | AT12: =IF(OR($AS25="",NOT(ISNUMBER($AS25)),$AH25=""),"",IF(INT($AS25)<=$AH25,"A tiempo","Fuera de término"))
AF13: =IF($AA26="","",IF(LEFT(UPPER(TRIM($AA26)),8)="FELICITA","N/A",IF($AE26="","",IFERROR(VLOOKUP(UPPER(TRIM($AE26)),Config!$A$6:$D$8,2,FALSE),IFERROR(VLOOKUP(IF(LEFT(UPPER(TRIM($AE26)),5)="SUPER","SUPER SALUD",IF(LEFT(UPPER(TRIM($AE26)),8)="SECRETAR","SECRETARIA DE SALUD",IF(LEFT(UPPER(TRIM($AE26)),4)="SEDE","SEDE",UPPER(TRIM($AE26))))),Config!$A$6:$D$8,2,FALSE),"⚠"))))) | AG13: =IF($AA26="","",IF(LEFT(UPPER(TRIM($AA26)),8)="FELICITA","N/A",IF($AE26="","",IFERROR(VLOOKUP(UPPER(TRIM($AE26)),Config!$A$6:$D$8,3,FALSE),IFERROR(VLOOKUP(IF(LEFT(UPPER(TRIM($AE26)),5)="SUPER","SUPER SALUD",IF(LEFT(UPPER(TRIM($AE26)),8)="SECRETAR","SECRETARIA DE SALUD",IF(LEFT(UPPER(TRIM($AE26)),4)="SEDE","SEDE",UPPER(TRIM($AE26))))),Config!$A$6:$D$8,3,FALSE),""))))) | AH13: =IF(OR($E26="",NOT(ISNUMBER($E26)),$AF26="",$AF26="N/A",NOT(ISNUMBER($AF26))),"",IF($AG26="Hábiles",WORKDAY(INT($E26),$AF26,Config!$F$6:$F$39),INT($E26)+$AF26)) | AI13: =IF($E26="","",IF(LEFT(UPPER(TRIM($AA26)),8)="FELICITA","⭐ Felicitación",IF(NOT(ISNUMBER($E26)),"⚠ Revisar fecha",IF(UPPER(TRIM($AK26))="RESPONDIDA - CERRADA","✅ Cerrada",IF($AE26="","⚠ Falta entidad",IF($AH26="","⚠ Revisar término",IF(TODAY()>$AH26,"🔴 Vencida",IF($AH26-TODAY()<=Config!$B$12,"🟡 Próxima a vencer","🟢 En término")))))))) | AJ13: =IF(OR($E26="",NOT(ISNUMBER($E26))),"",IF(ISNUMBER($AS26),MAX(0,INT($AS26)-INT($E26)),MAX(0,TODAY()-INT($E26)))) | AT13: =IF(OR($AS26="",NOT(ISNUMBER($AS26)),$AH26=""),"",IF(INT($AS26)<=$AH26,"A tiempo","Fuera de término"))
AF14: =IF($AA27="","",IF(LEFT(UPPER(TRIM($AA27)),8)="FELICITA","N/A",IF($AE27="","",IFERROR(VLOOKUP(UPPER(TRIM($AE27)),Config!$A$6:$D$8,2,FALSE),IFERROR(VLOOKUP(IF(LEFT(UPPER(TRIM($AE27)),5)="SUPER","SUPER SALUD",IF(LEFT(UPPER(TRIM($AE27)),8)="SECRETAR","SECRETARIA DE SALUD",IF(LEFT(UPPER(TRIM($AE27)),4)="SEDE","SEDE",UPPER(TRIM($AE27))))),Config!$A$6:$D$8,2,FALSE),"⚠"))))) | AG14: =IF($AA27="","",IF(LEFT(UPPER(TRIM($AA27)),8)="FELICITA","N/A",IF($AE27="","",IFERROR(VLOOKUP(UPPER(TRIM($AE27)),Config!$A$6:$D$8,3,FALSE),IFERROR(VLOOKUP(IF(LEFT(UPPER(TRIM($AE27)),5)="SUPER","SUPER SALUD",IF(LEFT(UPPER(TRIM($AE27)),8)="SECRETAR","SECRETARIA DE SALUD",IF(LEFT(UPPER(TRIM($AE27)),4)="SEDE","SEDE",UPPER(TRIM($AE27))))),Config!$A$6:$D$8,3,FALSE),""))))) | AH14: =IF(OR($E27="",NOT(ISNUMBER($E27)),$AF27="",$AF27="N/A",NOT(ISNUMBER($AF27))),"",IF($AG27="Hábiles",WORKDAY(INT($E27),$AF27,Config!$F$6:$F$39),INT($E27)+$AF27)) | AI14: =IF($E27="","",IF(LEFT(UPPER(TRIM($AA27)),8)="FELICITA","⭐ Felicitación",IF(NOT(ISNUMBER($E27)),"⚠ Revisar fecha",IF(UPPER(TRIM($AK27))="RESPONDIDA - CERRADA","✅ Cerrada",IF($AE27="","⚠ Falta entidad",IF($AH27="","⚠ Revisar término",IF(TODAY()>$AH27,"🔴 Vencida",IF($AH27-TODAY()<=Config!$B$12,"🟡 Próxima a vencer","🟢 En término")))))))) | AJ14: =IF(OR($E27="",NOT(ISNUMBER($E27))),"",IF(ISNUMBER($AS27),MAX(0,INT($AS27)-INT($E27)),MAX(0,TODAY()-INT($E27)))) | AT14: =IF(OR($AS27="",NOT(ISNUMBER($AS27)),$AH27=""),"",IF(INT($AS27)<=$AH27,"A tiempo","Fuera de término"))
AF15: =IF($AA28="","",IF(LEFT(UPPER(TRIM($AA28)),8)="FELICITA","N/A",IF($AE28="","",IFERROR(VLOOKUP(UPPER(TRIM($AE28)),Config!$A$6:$D$8,2,FALSE),IFERROR(VLOOKUP(IF(LEFT(UPPER(TRIM($AE28)),5)="SUPER","SUPER SALUD",IF(LEFT(UPPER(TRIM($AE28)),8)="SECRETAR","SECRETARIA DE SALUD",IF(LEFT(UPPER(TRIM($AE28)),4)="SEDE","SEDE",UPPER(TRIM($AE28))))),Config!$A$6:$D$8,2,FALSE),"⚠"))))) | AG15: =IF($AA28="","",IF(LEFT(UPPER(TRIM($AA28)),8)="FELICITA","N/A",IF($AE28="","",IFERROR(VLOOKUP(UPPER(TRIM($AE28)),Config!$A$6:$D$8,3,FALSE),IFERROR(VLOOKUP(IF(LEFT(UPPER(TRIM($AE28)),5)="SUPER","SUPER SALUD",IF(LEFT(UPPER(TRIM($AE28)),8)="SECRETAR","SECRETARIA DE SALUD",IF(LEFT(UPPER(TRIM($AE28)),4)="SEDE","SEDE",UPPER(TRIM($AE28))))),Config!$A$6:$D$8,3,FALSE),""))))) | AH15: =IF(OR($E28="",NOT(ISNUMBER($E28)),$AF28="",$AF28="N/A",NOT(ISNUMBER($AF28))),"",IF($AG28="Hábiles",WORKDAY(INT($E28),$AF28,Config!$F$6:$F$39),INT($E28)+$AF28)) | AI15: =IF($E28="","",IF(LEFT(UPPER(TRIM($AA28)),8)="FELICITA","⭐ Felicitación",IF(NOT(ISNUMBER($E28)),"⚠ Revisar fecha",IF(UPPER(TRIM($AK28))="RESPONDIDA - CERRADA","✅ Cerrada",IF($AE28="","⚠ Falta entidad",IF($AH28="","⚠ Revisar término",IF(TODAY()>$AH28,"🔴 Vencida",IF($AH28-TODAY()<=Config!$B$12,"🟡 Próxima a vencer","🟢 En término")))))))) | AJ15: =IF(OR($E28="",NOT(ISNUMBER($E28))),"",IF(ISNUMBER($AS28),MAX(0,INT($AS28)-INT($E28)),MAX(0,TODAY()-INT($E28)))) | AT15: =IF(OR($AS28="",NOT(ISNUMBER($AS28)),$AH28=""),"",IF(INT($AS28)<=$AH28,"A tiempo","Fuera de término"))
AF16: =IF($AA29="","",IF(LEFT(UPPER(TRIM($AA29)),8)="FELICITA","N/A",IF($AE29="","",IFERROR(VLOOKUP(UPPER(TRIM($AE29)),Config!$A$6:$D$8,2,FALSE),IFERROR(VLOOKUP(IF(LEFT(UPPER(TRIM($AE29)),5)="SUPER","SUPER SALUD",IF(LEFT(UPPER(TRIM($AE29)),8)="SECRETAR","SECRETARIA DE SALUD",IF(LEFT(UPPER(TRIM($AE29)),4)="SEDE","SEDE",UPPER(TRIM($AE29))))),Config!$A$6:$D$8,2,FALSE),"⚠"))))) | AG16: =IF($AA29="","",IF(LEFT(UPPER(TRIM($AA29)),8)="FELICITA","N/A",IF($AE29="","",IFERROR(VLOOKUP(UPPER(TRIM($AE29)),Config!$A$6:$D$8,3,FALSE),IFERROR(VLOOKUP(IF(LEFT(UPPER(TRIM($AE29)),5)="SUPER","SUPER SALUD",IF(LEFT(UPPER(TRIM($AE29)),8)="SECRETAR","SECRETARIA DE SALUD",IF(LEFT(UPPER(TRIM($AE29)),4)="SEDE","SEDE",UPPER(TRIM($AE29))))),Config!$A$6:$D$8,3,FALSE),""))))) | AH16: =IF(OR($E29="",NOT(ISNUMBER($E29)),$AF29="",$AF29="N/A",NOT(ISNUMBER($AF29))),"",IF($AG29="Hábiles",WORKDAY(INT($E29),$AF29,Config!$F$6:$F$39),INT($E29)+$AF29)) | AI16: =IF($E29="","",IF(LEFT(UPPER(TRIM($AA29)),8)="FELICITA","⭐ Felicitación",IF(NOT(ISNUMBER($E29)),"⚠ Revisar fecha",IF(UPPER(TRIM($AK29))="RESPONDIDA - CERRADA","✅ Cerrada",IF($AE29="","⚠ Falta entidad",IF($AH29="","⚠ Revisar término",IF(TODAY()>$AH29,"🔴 Vencida",IF($AH29-TODAY()<=Config!$B$12,"🟡 Próxima a vencer","🟢 En término")))))))) | AJ16: =IF(OR($E29="",NOT(ISNUMBER($E29))),"",IF(ISNUMBER($AS29),MAX(0,INT($AS29)-INT($E29)),MAX(0,TODAY()-INT($E29)))) | AT16: =IF(OR($AS29="",NOT(ISNUMBER($AS29)),$AH29=""),"",IF(INT($AS29)<=$AH29,"A tiempo","Fuera de término"))
... AF391: =IF($AA404="","",IF(LEFT(UPPER(TRIM($AA404)),8)="FELICITA","N/A",IF($AE404="","",IFERROR(VLOOKUP(UPPER(TRIM($AE404)),Config!$A$6:$D$8,2,FALSE),IFERROR(VLOOKUP(IF(LEFT(UPPER(TRIM($AE404)),5)="SUPER","SUPER SALUD",IF(LEFT(UPPER(TRIM($AE404)),8)="SECRETAR","SECRETARIA DE SALUD",IF(LEFT(UPPER(TRIM($AE404)),4)="SEDE","SEDE",UPPER(TRIM($AE404))))),Config!$A$6:$D$8,2,FALSE),"⚠"))))) | AG391: =IF($AA404="","",IF(LEFT(UPPER(TRIM($AA404)),8)="FELICITA","N/A",IF($AE404="","",IFERROR(VLOOKUP(UPPER(TRIM($AE404)),Config!$A$6:$D$8,3,FALSE),IFERROR(VLOOKUP(IF(LEFT(UPPER(TRIM($AE404)),5)="SUPER","SUPER SALUD",IF(LEFT(UPPER(TRIM($AE404)),8)="SECRETAR","SECRETARIA DE SALUD",IF(LEFT(UPPER(TRIM($AE404)),4)="SEDE","SEDE",UPPER(TRIM($AE404))))),Config!$A$6:$D$8,3,FALSE),""))))) | AH391: =IF(OR($E404="",NOT(ISNUMBER($E404)),$AF404="",$AF404="N/A",NOT(ISNUMBER($AF404))),"",IF($AG404="Hábiles",WORKDAY(INT($E404),$AF404,Config!$F$6:$F$39),INT($E404)+$AF404)) | AI391: =IF($E404="","",IF(LEFT(UPPER(TRIM($AA404)),8)="FELICITA","⭐ Felicitación",IF(NOT(ISNUMBER($E404)),"⚠ Revisar fecha",IF(UPPER(TRIM($AK404))="RESPONDIDA - CERRADA","✅ Cerrada",IF($AE404="","⚠ Falta entidad",IF($AH404="","⚠ Revisar término",IF(TODAY()>$AH404,"🔴 Vencida",IF($AH404-TODAY()<=Config!$B$12,"🟡 Próxima a vencer","🟢 En término")))))))) | AJ391: =IF(OR($E404="",NOT(ISNUMBER($E404))),"",IF(ISNUMBER($AS404),MAX(0,INT($AS404)-INT($E404)),MAX(0,TODAY()-INT($E404)))) | AT391: =IF(OR($AS404="",NOT(ISNUMBER($AS404)),$AH404=""),"",IF(INT($AS404)<=$AH404,"A tiempo","Fuera de término"))

Sheet Trazabilidad
A1: 🧭 TRAZABILIDAD
A2: Cada acción de la plataforma queda registrada aquí. No editar.
A4: FECHA Y HORA | B4: RADICADO | C4: ACCIÓN | D4: DETALLE | E4: USUARIO

Sheet Responsables
A1: 📇 RESPONSABLES DE GESTIÓN
A2: Se administra desde la plataforma (módulo Responsables). El correo es al que llega la notificación.
A4: ID | B4: ÁREA / SERVICIO | C4: NOMBRE | D4: CARGO | E4: CORREO | F4: TELÉFONO | G4: ACTIVO
A5: 1 | B5: SIAU – Oficina de Atención al Usuario | G5: SI
A6: 2 | B6: CALIDAD – Subgerencia | G6: SI
A7: 3 | B7: CALIDAD – Profesional | G7: SI
A8: 4 | B8: CALIDAD – Profesional | G8: NO
A9: 5 | B9: GERENCIA | G9: SI
A10: 6 | B10: ALIMENTACIÓN | G10: SI
A11: 7 | B11: CIRUGÍA | G11: SI
A12: 8 | B12: CONSULTA EXTERNA | G12: SI
A13: 9 | B13: CUIDADO INTENSIVO ADULTOS | G13: SI
A14: 10 | B14: CUIDADO INTENSIVO NEONATAL | G14: SI
A15: 11 | B15: CUIDADO INTENSIVO PEDIÁTRICO | G15: SI
A16: 12 | B16: CUIDADO INTERMEDIO ADULTOS | G16: SI
... A32: 28 | B32: AUTORIZACIONES | G32: SI

Sheet Mapeo_Formulario
A1: 🔗 MAPEO DEL GOOGLE FORM EXISTENTE
A2: Se configura desde la plataforma (Configuración ▸ Vincular formulario). Aquí queda el resultado.
A4: PREGUNTA DEL FORMULARIO (título exacto) | B4: CAMPO DEL SISTEMA | D4: CAMPOS DISPONIBLES
A5: Tipo de solicitud | B5: tipoPqrs | D5: (no importar)
A6: Usted es: | B6: tipoSolicitante | D6: canal
A7: Tipo de documento | B7: tipoDocSolicitante | D7: fechaPqrs
A8: Número de identificación. | B8: numDocSolicitante | D8: fechaRecepcion
A9: Nombre completo del paciente: | B9: nombreSolicitante | D9: tipoSolicitante
A10: Edad | B10: edad | D10: tipoDocSolicitante
A11: Sexo | B11: sexo | D11: numDocSolicitante
A12: Número de teléfono | B12: telefono | D12: nombreSolicitante
A13: Dirección. | B13: direccion | D13: telefono
A14: Correo electrónico. | B14: correo | D14: correo
A15: Población diferencial. | B15: poblacion | D15: direccion
... A20: Describa su solicitud. | B20: descripcion | D20: sexo
D21: poblacion
D22: eps
D23: regimen
D24: sede
D25: servicio
D26: servicioEspecifico
D27: modalidad
D28: tipoPqrs
D29: descripcion
D30: entidad
D31: observaciones

Sheet Config
A1: ⚙ CONFIGURACIÓN DEL SISTEMA PQRS
A2: La plataforma lee estos rangos por posición: no muevas filas ni columnas.
A4: TÉRMINOS LEGALES DE RESPUESTA | F4: FESTIVOS
A5: ENTIDAD | B5: DÍAS | C5: TIPO DE DÍA | D5: NORMA | F5: FECHA | G5: DESCRIPCIÓN
A6: SEDE | B6: 15 | C6: Hábiles | D6: Ley 1755 de 2015 – Derecho de petición | F6: 45658 | G6: Año Nuevo
A7: SUPER SALUD | B7: 1 | C7: Calendario | D7: Circular SuperSalud – Prioritario/Vital (24 h) | F7: 45663 | G7: Reyes
A8: SECRETARIA DE SALUD | B8: 3 | C8: Calendario | D8: Ley 1438 de 2011 – Ente territorial (72 h) | F8: 45740 | G8: San José
F9: 45764 | G9: Jueves Santo
A10: PARÁMETROS | F10: 45765 | G10: Viernes Santo
A11: Base de consecutivo histórico | B11: 3174 | F11: 45778 | G11: Trabajo
A12: Umbral alerta amarilla (días) | B12: 3 | F12: 45810 | G12: Ascensión
A13: Prefijo del radicado | B13: SIAU | F13: 45831 | G13: Corpus Christi
A14: Correo de la oficina SIAU | B14: siau@miredips.org | F14: 45838 | G14: Sagrado Corazón
A15: Teléfono SIAU | B15: (605) 322 5919 | F15: 45858 | G15: Independencia
A16: WhatsApp SIAU | B16: 315 405 6834 | F16: 45876 | G16: Boyacá
A17: ID del Google Form vinculado | F17: 45887 | G17: Asunción
A18: Nombre de la hoja de respuestas del Form | B18: Respuesta de formulario 1 | F18: 45943 | G18: Raza
F19: 45964 | G19: Todos los Santos
F20: 45978 | G20: Indep. Cartagena
F21: 45999 | G21: Inmaculada
F22: 46016 | G22: Navidad
F23: 46023 | G23: Año Nuevo
F24: 46034 | G24: Reyes
F25: 46104 | G25: San José
F26: 46114 | G26: Jueves Santo
F27: 46115 | G27: Viernes Santo
F28: 46143 | G28: Trabajo
F29: 46181 | G29: Corpus Christi
F30: 46188 | G30: Sagrado Corazón
... F39: 46381 | G39: Navidad
A42: LISTAS DESPLEGABLES (la plataforma las carga desde aquí)
A43: SEDE | B43: SERVICIO | C43: EPS / PRESTADOR | D43: CANAL | E43: TIPO DE PQRS | F43: TIPO SOLICITANTE | G43: TIPO DOCUMENTO | H43: ENTIDAD PRESENTADA | I43: ESTADO | J43: SEXO | K43: RÉGIMEN | L43: POBLACIÓN DIFERENCIAL | M43: MODALIDAD DE ATENCIÓN | N43: TIPOLOGÍA
A44: C. ADELITA DE CHAR | B44: ADMISIONES | C44: NUEVA EPS | D44: Presencial - Buzón de sugerencias | E44: DENUNCIA | F44: USUARIO | G44: CEDULA DE CIUDADANIA | H44: SEDE | I44: Recibida | J44: FEMENINO | K44: SUBSIDIADO | L44: No aplica | M44: Presencial | N44: T1 Oportunidad en citas
A45: C. BOSQUES DE MARIA | B45: ALIMENTACIÓN | C45: MUTUAL SER EPS | D45: QR - Formulario | E45: FELICITACION | F45: COLABORADOR | G45: CEDULA DE EXTRANJERIA | H45: SUPERSALUD | I45: En análisis | J45: MASCULINO | K45: CONTRIBUTIVO | L45: Gestante | M45: Telemedicina | N45: T2 Entrega de medicamentos
A46: C. CIUDADELA | B46: APOYO DIAGNOSTICO | C46: COOSALUD EPS | D46: Correo electrónico | E46: PETICIÓN | F46: ACUDIENTE | G46: TARJETA DE IDENTIDAD | H46: SECRETARIA DE SALUD | I46: En gestión | J46: OTRO | K46: PARTICULAR | L46: Discapacidad | M46: Extramural | N46: T3 Programación de cirugías
A47: C. LA MANGA | B47: ASIGNACIÓN DE CITAS | C47: PROTEGER EPS | D47: Telefónico | E47: QUEJA | F47: FAMILIAR | G47: REGISTRO CIVIL | H47: EPS | I47: Respondida - Cerrada | K47: BENEFICIARIO | L47: Víctima del conflicto | N47: T4 Trato del personal
A48: C. LA PLAYA | B48: ATENCIÓN AL USUARIO | C48: SALUD TOTAL EPS | D48: Redes sociales | E48: RECLAMO | F48: OTRO | G48: SALVACONDUCTO | K48: OTRO | L48: Indígena | N48: T5 Autorizaciones y trámites
A49: C. LUZ CHINITA | B49: AUTORIZACIONES | C49: EPS SANITAS | E49: SOLICITUD | G49: PASAPORTE | L49: Afrodescendiente | N49: T6 Infraestructura y aseo
A50: C. MURILLO | B50: CALL CENTER | C50: EPS SURA | E50: SUGERENCIA | G50: PERMISO POR PROTECCION TEMPORAL | L50: Adulto mayor | N50: T7 Facturación
A51: C. NAZARETH | B51: CIRUGÍA | C51: FAMISANAR EPS | E51: TUTELA | G51: PERMISO ESPECIAL DE PERMANENCIA | L51: Menor de edad | N51: T8 Otra
...
